Workbook
Name N11N200: #REF!
Name N11N200: #REF!
Name N11N200: #REF!
Name TEST0: #REF!
Name TEST0: #REF!
Name TEST0: #REF!
Name TESTHKEY: #REF!
Name TESTHKEY: #REF!
Name TESTHKEY: #REF!
Name TESTKEYS: #REF!
Name TESTKEYS: #REF!
Name TESTKEYS: #REF!
Name TESTVKEY: #REF!
Name TESTVKEY: #REF!
Name TESTVKEY: #REF!

Sheet Cod Planos
A1: Plano | B1: Descrição do Plano | C1: Qtd caracter | D1: Ciclo | E1: Unid. | F1: Texto Ciclo | G1: Horiz Abertura | H1: Contador - Planos de Paradas
A2: URRST3STP001 | B2: REP PREVENT MANUT SIST-P 1P1 | C2: 29 | D2: 1 | E2: PRD | F2: PARADA | G2: 100 | I2: =IF(E2="SMS",D2,IF(E2="DIA",D2/7,IF(E2="PRD","0",0))) -> 0 | K2: Nome do campo | M2: Descrição | O2: TABELA | P2: DIA
A3: URRST3STP002 | B3: REP PREVENT MANUT SIST-P 2P1 | C3: 29 | D3: 2 | E3: PRD | F3: 2 PARADAS | G3: 100 | I3: =IF(E3="SMS",D3,IF(E3="DIA",D3/7,IF(E3="PRD","0",0))) -> 0 | K3: PIano manutenção | M3: Número que identifica um plano de manutenção. | O3: CICLO | P3: TEXTO
A4: URRST3STP003 | B4: REP PREVENT MANUT SIST-P 2P2 | C4: 29 | D4: 2 | E4: PRD | F4: 2 PARADAS | G4: 100 | I4: =IF(E4="SMS",D4,IF(E4="DIA",D4/7,IF(E4="PRD","0",0))) -> 0 | M4: Formação: X X X XXX XXX XXX | O4: 1 | P4: DIÁRIO
A5: URRST3STP004 | B5: REP PREVENT MANUT SIST-P 3P1 | C5: 29 | D5: 3 | E5: PRD | F5: 3 PARADAS | G5: 35 | I5: =IF(E5="SMS",D5,IF(E5="DIA",D5/7,IF(E5="PRD","0",0))) -> 0 | M5: 1 2 3 4 5 6 | O5: 2 | P5: 2 DIAS
A6: URRST3STP005 | B6: REP PREVENT MANUT SIST-P 3P2 | C6: 29 | D6: 3 | E6: PRD | F6: 3 PARADAS | G6: 35 | I6: =IF(E6="SMS",D6,IF(E6="DIA",D6/7,IF(E6="PRD","0",0))) -> 0 | M6: U R R ST2 STC 001 | O6: 3 | P6: 3 DIAS
A7: URRST3STP006 | B7: REP PREVENT MANUT SIST-P 3P3 | C7: 29 | D7: 3 | E7: PRD | F7: 3 PARADAS | G7: 35 | I7: =IF(E7="SMS",D7,IF(E7="DIA",D7/7,IF(E7="PRD","0",0))) -> 0 | O7: 4 | P7: 4 DIAS
A8: URRST3STP007 | B8: REP PREVENT MANUT SIST-P 6P1 | C8: 29 | D8: 6 | E8: PRD | F8: 6 PARADAS | G8: 65 | I8: =IF(E8="SMS",D8,IF(E8="DIA",D8/7,IF(E8="PRD","0",0))) -> 0 | K8: Cód. | L8: Descrição | M8: Padrão | O8: 5 | P8: 5 DIAS
A9: URRST3STP008 | B9: REP PREVENT MANUT SIST-P 6P2 | C9: 29 | D9: 6 | E9: PRD | F9: 6 PARADAS | G9: 65 | I9: =IF(E9="SMS",D9,IF(E9="DIA",D9/7,IF(E9="PRD","0",0))) -> 0 | K9: 1 | L9: Centro Produtivo | M9: C – Usiminas Cubatão
A10: URRST3STP009 | B10: REP PREVENT MANUT SIST-P 6P3 | C10: 29 | D10: 6 | E10: PRD | F10: 6 PARADAS | G10: 65 | I10: =IF(E10="SMS",D10,IF(E10="DIA",D10/7,IF(E10="PRD","0",0))) -> 0 | M10: G – Unigal
A11: URRST3STP010 | B11: REP PREVENT MANUT SIST-P 6P4 | C11: 29 | D11: 6 | E11: PRD | F11: 6 PARADAS | G11: 65 | I11: =IF(E11="SMS",D11,IF(E11="DIA",D11/7,IF(E11="PRD","0",0))) -> 0 | M11: U – Usiminas Ipatinga
A12: URRST3STP011 | B12: REP PREVENT MANUT SIST-P 6P5 | C12: 29 | D12: 6 | E12: PRD | F12: 6 PARADAS | G12: 65 | I12: =IF(E12="SMS",D12,IF(E12="DIA",D12/7,IF(E12="PRD","0",0))) -> 0 | K12: 2 | L12: Identificação do Processo | M12: R – Redução
A13: URRST3STP012 | B13: REP PREVENT MANUT SIST-P 6P6 | C13: 29 | D13: 6 | E13: PRD | F13: 6 PARADAS | G13: 65 | I13: =IF(E13="SMS",D13,IF(E13="DIA",D13/7,IF(E13="PRD","0",0))) -> 0 | M13: A – Aciaria
A14: URRST3STP013 | B14: REP PREVENT MANUT SIST-P 12P1 | C14: 30 | D14: 12 | E14: PRD | F14: 12 PARADAS | G14: 95 | I14: =IF(E14="SMS",D14,IF(E14="DIA",D14/7,IF(E14="PRD","0",0))) -> 0 | M14: Q – Laminação à Quente
A15: URRST3STP014 | B15: REP PREVENT MANUT SIST-P 12P2 | C15: 30 | D15: 12 | E15: PRD | F15: 12 PARADAS | G15: 95 | I15: =IF(E15="SMS",D15,IF(E15="DIA",D15/7,IF(E15="PRD","0",0))) -> 0 | M15: F – Laminação à Frio
A16: URRST3STP015 | B16: REP PREVENT MANUT SIST-P 12P3 | C16: 30 | D16: 12 | E16: PRD | F16: 12 PARADAS | G16: 95 | I16: =IF(E16="SMS",D16,IF(E16="DIA",D16/7,IF(E16="PRD","0",0))) -> 0 | M16: E – Energia e transporte
A17: URRST3STP016 | B17: REP PREVENT MANUT SIST-P 12P4 | C17: 30 | D17: 12 | E17: PRD | F17: 12 PARADAS | G17: 95 | I17: =IF(E17="SMS",D17,IF(E17="DIA",D17/7,IF(E17="PRD","0",0))) -> 0 | M17: I – Instrumentação e Automação
A18: URRST3STP017 | B18: REP PREVENT MANUT SIST-P 12P5 | C18: 30 | D18: 12 | E18: PRD | F18: 12 PARADAS | G18: 95 | I18: =IF(E18="SMS",D18,IF(E18="DIA",D18/7,IF(E18="PRD","0",0))) -> 0 | M18: M – Manutenção Central
A19: URRST3STP018 | B19: REP PREVENT MANUT SIST-P 12P6 | C19: 30 | D19: 12 | E19: PRD | F19: 12 PARADAS | G19: 95 | I19: =IF(E19="SMS",D19,IF(E19="DIA",D19/7,IF(E19="PRD","0",0))) -> 0 | K19: 3 | L19: Tipo de Plano | M19: I – Inspeção
A20: URRST3STP019 | B20: REP PREVENT MANUT SIST-P 12P7 | C20: 30 | D20: 12 | E20: PRD | F20: 12 PARADAS | G20: 95 | I20: =IF(E20="SMS",D20,IF(E20="DIA",D20/7,IF(E20="PRD","0",0))) -> 0 | M20: L – Lubrificação
A21: URRST3STP020 | B21: REP PREVENT MANUT SIST-P 12P8 | C21: 30 | D21: 12 | E21: PRD | F21: 12 PARADAS | G21: 95 | I21: =IF(E21="SMS",D21,IF(E21="DIA",D21/7,IF(E21="PRD","0",0))) -> 0 | M21: P – Preditiva
A22: URRST3STP021 | B22: REP PREVENT MANUT SIST-P 12P9 | C22: 30 | D22: 12 | E22: PRD | F22: 12 PARADAS | G22: 95 | I22: =IF(E22="SMS",D22,IF(E22="DIA",D22/7,IF(E22="PRD","0",0))) -> 0 | M22: E – Espoleta
A23: URRST3STP022 | B23: REP PREVENT MANUT SIST-P 12P10 | C23: 31 | D23: 12 | E23: PRD | F23: 12 PARADAS | G23: 95 | I23: =IF(E23="SMS",D23,IF(E23="DIA",D23/7,IF(E23="PRD","0",0))) -> 0 | M23: R – Reparo por Oferta
A24: URRST3STP023 | B24: REP PREVENT MANUT SIST-P 12P11 | C24: 31 | D24: 12 | E24: PRD | F24: 12 PARADAS | G24: 95 | I24: =IF(E24="SMS",D24,IF(E24="DIA",D24/7,IF(E24="PRD","0",0))) -> 0 | M24: O - Operação
A25: URRST3STP024 | B25: REP PREVENT MANUT SIST-P 12P12 | C25: 31 | D25: 12 | E25: PRD | F25: 12 PARADAS | G25: 95 | I25: =IF(E25="SMS",D25,IF(E25="DIA",D25/7,IF(E25="PRD","0",0))) -> 0
C26: =LEN(B26) -> 0 | E26: SMS | F26: =IF(E26=$L$31,VLOOKUP(D26,$K$33:$M$47,3,FALSE),IF(E26=$L$57,VLOOKUP(D26,$K$59:$L$116,2,FALSE),VLOOKUP(D26,$O$4:$P$8,2,FALSE))) -> #N/A | G26: =VLOOKUP(D26,$K$33:$N$48,4,FALSE) -> #N/A | I26: =IF(E26="SMS",D26,IF(E26="DIA",D26/7,IF(E26="PRD","0",0))) -> 0 | K26: 4 | L26: Linha Produção | M26: Linha de produção: ST2, ST3... - Sinter 2
A27: URRST3STE001 | B27: REP PREVENT MANUT SIST-E 1P1 | C27: 29 | D27: 1 | E27: PRD | F27: PARADA | G27: 100 | I27: =IF(E27="SMS",D27,IF(E27="DIA",D27/7,IF(E27="PRD","0",0))) -> 0 | K27: 5 | L27: Sub área | M27: STC - Sistema C
A28: URRST3STE002 | B28: REP PREVENT MANUT SIST-E 2P1 | C28: 29 | D28: 2 | E28: PRD | F28: 2 PARADAS | G28: 100 | I28: =IF(E28="SMS",D28,IF(E28="DIA",D28/7,IF(E28="PRD","0",0))) -> 0 | K28: 6 | L28: Numeração | M28: Ciclo: 01 a ZZ
A29: URRST3STE003 | B29: REP PREVENT MANUT SIST-E 2P2 | C29: 29 | D29: 2 | E29: PRD | F29: 2 PARADAS | G29: 100 | I29: =IF(E29="SMS",D29,IF(E29="DIA",D29/7,IF(E29="PRD","0",0))) -> 0
A30: URRST3STE004 | B30: REP PREVENT MANUT SIST-E 3P1 | C30: 29 | D30: 3 | E30: PRD | F30: 3 PARADAS | G30: 35 | I30: =IF(E30="SMS",D30,IF(E30="DIA",D30/7,IF(E30="PRD","0",0))) -> 0
A31: URRST3STE005 | B31: REP PREVENT MANUT SIST-E 3P2 | C31: 29 | D31: 3 | E31: PRD | F31: 3 PARADAS | G31: 35 | I31: =IF(E31="SMS",D31,IF(E31="DIA",D31/7,IF(E31="PRD","0",0))) -> 0 | K31: TABELA | L31: SMS | Y31: INSPEÇÃO | AA31: REPARO
A32: URRST3STE006 | B32: REP PREVENT MANUT SIST-E 3P3 | C32: 29 | D32: 3 | E32: PRD | F32: 3 PARADAS | G32: 35 | I32: =IF(E32="SMS",D32,IF(E32="DIA",D32/7,IF(E32="PRD","0",0))) -> 0 | K32: CICLO | L32: UNIDADE | M32: TEXTO DO CICLO | N32: HORIZONTE DE ABERTURA
A33: URRST3STE007 | B33: REP PREVENT MANUT SIST-E 6P1 | C33: 29 | D33: 6 | E33: PRD | F33: 6 PARADAS | G33: 65 | I33: =IF(E33="SMS",D33,IF(E33="DIA",D33/7,IF(E33="PRD","0",0))) -> 0 | K33: 1 | L33: SMS | M33: SEMANAL | N33: 100
A34: URRST3STE008 | B34: REP PREVENT MANUT SIST-E 6P2 | C34: 29 | D34: 6 | E34: PRD | F34: 6 PARADAS | G34: 65 | I34: =IF(E34="SMS",D34,IF(E34="DIA",D34/7,IF(E34="PRD","0",0))) -> 0 | K34: 2 | L34: SMS | M34: 2 SEMANAS | N34: 100
A35: URRST3STE009 | B35: REP PREVENT MANUT SIST-E 6P3 | C35: 29 | D35: 6 | E35: PRD | F35: 6 PARADAS | G35: 65 | I35: =IF(E35="SMS",D35,IF(E35="DIA",D35/7,IF(E35="PRD","0",0))) -> 0 | K35: 3 | L35: SMS | M35: 3 SEMANAS | N35: 35
A36: URRST3STE010 | B36: REP PREVENT MANUT SIST-E 6P4 | C36: 29 | D36: 6 | E36: PRD | F36: 6 PARADAS | G36: 65 | I36: =IF(E36="SMS",D36,IF(E36="DIA",D36/7,IF(E36="PRD","0",0))) -> 0 | K36: 4 | L36: SMS | M36: 4 SEMANAS = 1M | N36: 50
A37: URRST3STE011 | B37: REP PREVENT MANUT SIST-E 6P5 | C37: 29 | D37: 6 | E37: PRD | F37: 6 PARADAS | G37: 65 | I37: =IF(E37="SMS",D37,IF(E37="DIA",D37/7,IF(E37="PRD","0",0))) -> 0 | K37: 6 | L37: SMS | M37: 6 SEMANAS | N37: 65
A38: URRST3STE012 | B38: REP PREVENT MANUT SIST-E 6P6 | C38: 29 | D38: 6 | E38: PRD | F38: 6 PARADAS | G38: 65 | I38: =IF(E38="SMS",D38,IF(E38="DIA",D38/7,IF(E38="PRD","0",0))) -> 0 | K38: 9 | L38: SMS | M38: 9 SEMANAS = 2M | N38: 65
A39: URRST3STE013 | B39: REP PREVENT MANUT SIST-E 12P1 | C39: 30 | D39: 12 | E39: PRD | F39: 12 PARADAS | G39: 95 | I39: =IF(E39="SMS",D39,IF(E39="DIA",D39/7,IF(E39="PRD","0",0))) -> 0 | K39: 13 | L39: SMS | M39: TRIMESTRAL = 3M | N39: 75
A40: URRST3STE014 | B40: REP PREVENT MANUT SIST-E 12P2 | C40: 30 | D40: 12 | E40: PRD | F40: 12 PARADAS | G40: 95 | I40: =IF(E40="SMS",D40,IF(E40="DIA",D40/7,IF(E40="PRD","0",0))) -> 0 | K40: 17 | L40: SMS | M40: 17 SEMANAS = 4M | N40: 80
...

Sheet ITENS
A1: Local de Instalação | B1: GPM | C1: CENTRO DE TRABALHO | D1: CONDIÇÃO | E1: PRIORIDADE | F1: PLANO REPARO | G1: Identificador | H1: CONTADOR | I1: DESCRIÇÃO ITEM | J1: QTD CARACTERES | K1: Descrição do Plano | L1: Ciclo | M1: unid. | N1: Texto Ciclo | O1: Horiz Abertura | P1: t(H) | Q1: Itens
R2: Criticidade PROVISÓRIA | XEY2: CICLO DE UMA PARADA | XEZ2: 3X CICLO DE UMA PARADA
A5: US01-RD-SINT3-SISTP-PRODU-GNMS3-SCT | B5: 041 | C5: R55E-041 | D5: P | E5: 0 | F5: URRST3STP001 | G5: 1 | I5: CAVALETE GN LIMPEZA PREV ELÉTRICA | J5: =LEN(I5) -> 33 | K5: =VLOOKUP(F5,'Cod Planos'!$A:$G,2,FALSE) -> REP PREVENT MANUT SIST-P 1P1 | L5: =VLOOKUP(F5,'Cod Planos'!$A:$G,4,FALSE) -> 1 | M5: =VLOOKUP(F5,'Cod Planos'!$A:$G,5,FALSE) -> PRD | N5: =VLOOKUP(F5,'Cod Planos'!$A:$G,6,FALSE) -> PARADA | O5: =VLOOKUP(F5,'Cod Planos'!$A:$G,7,FALSE) -> 100 | P5: 1 | Q5: =I5 -> CAVALETE GN LIMPEZA PREV ELÉTRICA | R5: CR01
A6: US01-RD-SINT3-SISTP-ARMAZ-TRMIS-SCT | B6: 041 | C6: R55E-041 | D6: P | E6: 0 | F6: URRST3STP004 | G6: 2 | I6: COMPORTA TREMONHA PREV ELÉTRICA | J6: =LEN(I6) -> 31 | K6: =VLOOKUP(F6,'Cod Planos'!$A:$G,2,FALSE) -> REP PREVENT MANUT SIST-P 3P1 | L6: =VLOOKUP(F6,'Cod Planos'!$A:$G,4,FALSE) -> 3 | M6: =VLOOKUP(F6,'Cod Planos'!$A:$G,5,FALSE) -> PRD | N6: =VLOOKUP(F6,'Cod Planos'!$A:$G,6,FALSE) -> 3 PARADAS | O6: =VLOOKUP(F6,'Cod Planos'!$A:$G,7,FALSE) -> 35 | P6: 2 | Q6: =I6 -> COMPORTA TREMONHA PREV ELÉTRICA | R6: CR01
A7: US01-RD-SINT3-SISTP-ARMAZ-TRMIS-SCT | B7: 041 | C7: R55E-041 | D7: P | E7: 0 | F7: URRST3STP001 | G7: 3 | I7: COMPORTA TREM LIMPEZA PREV ELÉTRICA | J7: =LEN(I7) -> 35 | K7: =VLOOKUP(F7,'Cod Planos'!$A:$G,2,FALSE) -> REP PREVENT MANUT SIST-P 1P1 | L7: =VLOOKUP(F7,'Cod Planos'!$A:$G,4,FALSE) -> 1 | M7: =VLOOKUP(F7,'Cod Planos'!$A:$G,5,FALSE) -> PRD | N7: =VLOOKUP(F7,'Cod Planos'!$A:$G,6,FALSE) -> PARADA | O7: =VLOOKUP(F7,'Cod Planos'!$A:$G,7,FALSE) -> 100 | P7: 1 | Q7: =I7 -> COMPORTA TREM LIMPEZA PREV ELÉTRICA | R7: CR01
A8: 10380837 | B8: 041 | C8: R55E-041 | D8: P | E8: 0 | F8: URRST3STP007 | G8: 4 | I8: COMPORTA TREMONHA MOTOR ELÉTRICO | J8: =LEN(I8) -> 32 | K8: =VLOOKUP(F8,'Cod Planos'!$A:$G,2,FALSE) -> REP PREVENT MANUT SIST-P 6P1 | L8: =VLOOKUP(F8,'Cod Planos'!$A:$G,4,FALSE) -> 6 | M8: =VLOOKUP(F8,'Cod Planos'!$A:$G,5,FALSE) -> PRD | N8: =VLOOKUP(F8,'Cod Planos'!$A:$G,6,FALSE) -> 6 PARADAS | O8: =VLOOKUP(F8,'Cod Planos'!$A:$G,7,FALSE) -> 65 | P8: 2 | Q8: =I8 -> COMPORTA TREMONHA MOTOR ELÉTRICO | R8: CR01
A9: 10384772 | B9: 041 | C9: R55E-041 | D9: P | E9: 0 | F9: URRST3STP004 | G9: 5 | I9: DETECTOR CAMADAS PREV ELÉTRICA | J9: =LEN(I9) -> 30 | K9: =VLOOKUP(F9,'Cod Planos'!$A:$G,2,FALSE) -> REP PREVENT MANUT SIST-P 3P1 | L9: =VLOOKUP(F9,'Cod Planos'!$A:$G,4,FALSE) -> 3 | M9: =VLOOKUP(F9,'Cod Planos'!$A:$G,5,FALSE) -> PRD | N9: =VLOOKUP(F9,'Cod Planos'!$A:$G,6,FALSE) -> 3 PARADAS | O9: =VLOOKUP(F9,'Cod Planos'!$A:$G,7,FALSE) -> 35 | P9: 4 | Q9: =I9 -> DETECTOR CAMADAS PREV ELÉTRICA | R9: CR01
A10: US01-RD-SINT3-SISTP-PREPA-R_ALI-SCT | B10: 041 | C10: R55E-041 | D10: P | E10: 0 | F10: URRST3STP004 | G10: 6 | I10: ROLO ALIMENT PREVENTIVA ELÉTRICA | J10: =LEN(I10) -> 32 | K10: =VLOOKUP(F10,'Cod Planos'!$A:$G,2,FALSE) -> REP PREVENT MANUT SIST-P 3P1 | L10: =VLOOKUP(F10,'Cod Planos'!$A:$G,4,FALSE) -> 3 | M10: =VLOOKUP(F10,'Cod Planos'!$A:$G,5,FALSE) -> PRD | N10: =VLOOKUP(F10,'Cod Planos'!$A:$G,6,FALSE) -> 3 PARADAS | O10: =VLOOKUP(F10,'Cod Planos'!$A:$G,7,FALSE) -> 35 | P10: 2 | Q10: =I10 -> ROLO ALIMENT PREVENTIVA ELÉTRICA | R10: CR01
A11: 10380863 | B11: 041 | C11: R55E-041 | D11: P | E11: 0 | F11: URRST3STP007 | G11: 7 | I11: ROLO ALIMENTADOR MOTOR ACIONAMENTO | J11: =LEN(I11) -> 34 | K11: =VLOOKUP(F11,'Cod Planos'!$A:$G,2,FALSE) -> REP PREVENT MANUT SIST-P 6P1 | L11: =VLOOKUP(F11,'Cod Planos'!$A:$G,4,FALSE) -> 6 | M11: =VLOOKUP(F11,'Cod Planos'!$A:$G,5,FALSE) -> PRD | N11: =VLOOKUP(F11,'Cod Planos'!$A:$G,6,FALSE) -> 6 PARADAS | O11: =VLOOKUP(F11,'Cod Planos'!$A:$G,7,FALSE) -> 65 | P11: 2 | Q11: =I11 -> ROLO ALIMENTADOR MOTOR ACIONAMENTO | R11: CR01
A12: US01-RD-SINT3-SISTP-PREPA-R_ALI-SCT | B12: 041 | C12: R55E-041 | D12: P | E12: 0 | F12: URRST3STP001 | G12: 8 | I12: ROLO ALIMENTADOR LIMPEZA PREV ELÉT | J12: =LEN(I12) -> 34 | K12: =VLOOKUP(F12,'Cod Planos'!$A:$G,2,FALSE) -> REP PREVENT MANUT SIST-P 1P1 | L12: =VLOOKUP(F12,'Cod Planos'!$A:$G,4,FALSE) -> 1 | M12: =VLOOKUP(F12,'Cod Planos'!$A:$G,5,FALSE) -> PRD | N12: =VLOOKUP(F12,'Cod Planos'!$A:$G,6,FALSE) -> PARADA | O12: =VLOOKUP(F12,'Cod Planos'!$A:$G,7,FALSE) -> 100 | P12: 1 | Q12: =I12 -> ROLO ALIMENTADOR LIMPEZA PREV ELÉT | R12: CR01
A13: 10384715 | B13: 041 | C13: R55E-041 | D13: P | E13: 0 | F13: URRST3STP004 | G13: 9 | I13: MONOVIA ISF PREVENTIVA ELÉTRICA | J13: =LEN(I13) -> 31 | K13: =VLOOKUP(F13,'Cod Planos'!$A:$G,2,FALSE) -> REP PREVENT MANUT SIST-P 3P1 | L13: =VLOOKUP(F13,'Cod Planos'!$A:$G,4,FALSE) -> 3 | M13: =VLOOKUP(F13,'Cod Planos'!$A:$G,5,FALSE) -> PRD | N13: =VLOOKUP(F13,'Cod Planos'!$A:$G,6,FALSE) -> 3 PARADAS | O13: =VLOOKUP(F13,'Cod Planos'!$A:$G,7,FALSE) -> 35 | P13: 4 | Q13: =I13 -> MONOVIA ISF PREVENTIVA ELÉTRICA | R13: CR01
A14: 10384774 | B14: 041 | C14: R55E-041 | D14: P | E14: 0 | F14: URRST3STP004 | G14: 10 | I14: MONOVIA 1 CAIXA VENTO PREV ELÉTRICA | J14: =LEN(I14) -> 35 | K14: =VLOOKUP(F14,'Cod Planos'!$A:$G,2,FALSE) -> REP PREVENT MANUT SIST-P 3P1 | L14: =VLOOKUP(F14,'Cod Planos'!$A:$G,4,FALSE) -> 3 | M14: =VLOOKUP(F14,'Cod Planos'!$A:$G,5,FALSE) -> PRD | N14: =VLOOKUP(F14,'Cod Planos'!$A:$G,6,FALSE) -> 3 PARADAS | O14: =VLOOKUP(F14,'Cod Planos'!$A:$G,7,FALSE) -> 35 | P14: 4 | Q14: =I14 -> MONOVIA 1 CAIXA VENTO PREV ELÉTRICA | R14: CR01
A15: 10384775 | B15: 041 | C15: R55E-041 | D15: P | E15: 0 | F15: URRST3STP004 | G15: 11 | I15: MONOVIA 2 CAIXA VENT PREV ELÉTRICA | J15: =LEN(I15) -> 34 | K15: =VLOOKUP(F15,'Cod Planos'!$A:$G,2,FALSE) -> REP PREVENT MANUT SIST-P 3P1 | L15: =VLOOKUP(F15,'Cod Planos'!$A:$G,4,FALSE) -> 3 | M15: =VLOOKUP(F15,'Cod Planos'!$A:$G,5,FALSE) -> PRD | N15: =VLOOKUP(F15,'Cod Planos'!$A:$G,6,FALSE) -> 3 PARADAS | O15: =VLOOKUP(F15,'Cod Planos'!$A:$G,7,FALSE) -> 35 | P15: 4 | Q15: =I15 -> MONOVIA 2 CAIXA VENT PREV ELÉTRICA | R15: CR01
A16: US01-RD-SINT3-SISTP-PRODU-ESTEI-SCT | B16: 041 | C16: R55E-041 | D16: P | E16: 0 | F16: URRST3STP004 | G16: 12 | I16: ESTEIRA MS3 PREVENTIVA ELÉTRICA | J16: =LEN(I16) -> 31 | K16: =VLOOKUP(F16,'Cod Planos'!$A:$G,2,FALSE) -> REP PREVENT MANUT SIST-P 3P1 | L16: =VLOOKUP(F16,'Cod Planos'!$A:$G,4,FALSE) -> 3 | M16: =VLOOKUP(F16,'Cod Planos'!$A:$G,5,FALSE) -> PRD | N16: =VLOOKUP(F16,'Cod Planos'!$A:$G,6,FALSE) -> 3 PARADAS | O16: =VLOOKUP(F16,'Cod Planos'!$A:$G,7,FALSE) -> 35 | P16: 2 | Q16: =I16 -> ESTEIRA MS3 PREVENTIVA ELÉTRICA | R16: CR01
A17: 10380906 | B17: 041 | C17: R55E-041 | D17: P | E17: 0 | F17: URRST3STP007 | G17: 13 | I17: ESTEIRA MS3 PREVENTIVA MOTOR | J17: =LEN(I17) -> 28 | K17: =VLOOKUP(F17,'Cod Planos'!$A:$G,2,FALSE) -> REP PREVENT MANUT SIST-P 6P1 | L17: =VLOOKUP(F17,'Cod Planos'!$A:$G,4,FALSE) -> 6 | M17: =VLOOKUP(F17,'Cod Planos'!$A:$G,5,FALSE) -> PRD | N17: =VLOOKUP(F17,'Cod Planos'!$A:$G,6,FALSE) -> 6 PARADAS | O17: =VLOOKUP(F17,'Cod Planos'!$A:$G,7,FALSE) -> 65 | P17: 2 | Q17: =I17 -> ESTEIRA MS3 PREVENTIVA MOTOR | R17: CR01
A18: US01-RD-SINT3-SISTP-PRODU-ESTEI-SCT | B18: 041 | C18: R55E-041 | D18: P | E18: 0 | F18: URRST3STP001 | G18: 14 | I18: ESTEIRA MS3 LIMPEZA PREV ELÉTRICA | J18: =LEN(I18) -> 33 | K18: =VLOOKUP(F18,'Cod Planos'!$A:$G,2,FALSE) -> REP PREVENT MANUT SIST-P 1P1 | L18: =VLOOKUP(F18,'Cod Planos'!$A:$G,4,FALSE) -> 1 | M18: =VLOOKUP(F18,'Cod Planos'!$A:$G,5,FALSE) -> PRD | N18: =VLOOKUP(F18,'Cod Planos'!$A:$G,6,FALSE) -> PARADA | O18: =VLOOKUP(F18,'Cod Planos'!$A:$G,7,FALSE) -> 100 | P18: 1 | Q18: =I18 -> ESTEIRA MS3 LIMPEZA PREV ELÉTRICA | R18: CR01
A19: US01-RD-SINT3-SISTP-PRODU-ESTEI-SLB | B19: 041 | C19: R55E-041 | D19: P | E19: 0 | F19: URRST3STP001 | G19: 15 | I19: SIST LUB EST/BRIT LIMPEZ PREV ELÉTR | J19: =LEN(I19) -> 35 | K19: =VLOOKUP(F19,'Cod Planos'!$A:$G,2,FALSE) -> REP PREVENT MANUT SIST-P 1P1 | L19: =VLOOKUP(F19,'Cod Planos'!$A:$G,4,FALSE) -> 1 | M19: =VLOOKUP(F19,'Cod Planos'!$A:$G,5,FALSE) -> PRD | N19: =VLOOKUP(F19,'Cod Planos'!$A:$G,6,FALSE) -> PARADA | O19: =VLOOKUP(F19,'Cod Planos'!$A:$G,7,FALSE) -> 100 | P19: 1 | Q19: =I19 -> SIST LUB EST/BRIT LIMPEZ PREV ELÉTR | R19: CR01
A20: US01-RD-SINT3-SISTP-PRODU-ESTEI-SLB | B20: 041 | C20: R55E-041 | D20: P | E20: 0 | F20: URRST3STP007 | G20: 16 | I20: SIST LUB EST/BRIT PREVENT MOTOR | J20: =LEN(I20) -> 31 | K20: =VLOOKUP(F20,'Cod Planos'!$A:$G,2,FALSE) -> REP PREVENT MANUT SIST-P 6P1 | L20: =VLOOKUP(F20,'Cod Planos'!$A:$G,4,FALSE) -> 6 | M20: =VLOOKUP(F20,'Cod Planos'!$A:$G,5,FALSE) -> PRD | N20: =VLOOKUP(F20,'Cod Planos'!$A:$G,6,FALSE) -> 6 PARADAS | O20: =VLOOKUP(F20,'Cod Planos'!$A:$G,7,FALSE) -> 65 | P20: 2 | Q20: =I20 -> SIST LUB EST/BRIT PREVENT MOTOR | R20: CR01
A21: US01-RD-SINT3-SISTP-PRODU-BR_PR-SCT | B21: 041 | C21: R55E-041 | D21: P | E21: 0 | F21: URRST3STP001 | G21: 17 | I21: BRITADOR PRIMÁRIO LIMPEZ PREV ELÉTR | J21: =LEN(I21) -> 35 | K21: =VLOOKUP(F21,'Cod Planos'!$A:$G,2,FALSE) -> REP PREVENT MANUT SIST-P 1P1 | L21: =VLOOKUP(F21,'Cod Planos'!$A:$G,4,FALSE) -> 1 | M21: =VLOOKUP(F21,'Cod Planos'!$A:$G,5,FALSE) -> PRD | N21: =VLOOKUP(F21,'Cod Planos'!$A:$G,6,FALSE) -> PARADA | O21: =VLOOKUP(F21,'Cod Planos'!$A:$G,7,FALSE) -> 100 | P21: 1 | Q21: =I21 -> BRITADOR PRIMÁRIO LIMPEZ PREV ELÉTR | R21: CR01
A22: 10380872 | B22: 041 | C22: R55E-041 | D22: P | E22: 0 | F22: URRST3STP007 | G22: 18 | I22: BRITADOR PRIMÁRIO PREVENT MOTOR | J22: =LEN(I22) -> 31 | K22: =VLOOKUP(F22,'Cod Planos'!$A:$G,2,FALSE) -> REP PREVENT MANUT SIST-P 6P1 | L22: =VLOOKUP(F22,'Cod Planos'!$A:$G,4,FALSE) -> 6 | M22: =VLOOKUP(F22,'Cod Planos'!$A:$G,5,FALSE) -> PRD | N22: =VLOOKUP(F22,'Cod Planos'!$A:$G,6,FALSE) -> 6 PARADAS | O22: =VLOOKUP(F22,'Cod Planos'!$A:$G,7,FALSE) -> 65 | P22: 2 | Q22: =I22 -> BRITADOR PRIMÁRIO PREVENT MOTOR | R22: CR01
A23: US01-RD-SINT3-SISTP-PRODU-BR_PR-SCT | B23: 041 | C23: R55E-041 | D23: P | E23: 0 | F23: URRST3STP004 | G23: 19 | I23: BRITADOR PRIMÁRIO PREVENT ELÉTRICA | J23: =LEN(I23) -> 34 | K23: =VLOOKUP(F23,'Cod Planos'!$A:$G,2,FALSE) -> REP PREVENT MANUT SIST-P 3P1 | L23: =VLOOKUP(F23,'Cod Planos'!$A:$G,4,FALSE) -> 3 | M23: =VLOOKUP(F23,'Cod Planos'!$A:$G,5,FALSE) -> PRD | N23: =VLOOKUP(F23,'Cod Planos'!$A:$G,6,FALSE) -> 3 PARADAS | O23: =VLOOKUP(F23,'Cod Planos'!$A:$G,7,FALSE) -> 35 | P23: 2 | Q23: =I23 -> BRITADOR PRIMÁRIO PREVENT ELÉTRICA | R23: CR01
A24: 10384731 | B24: 041 | C24: R55E-041 | D24: P | E24: 0 | F24: URRST3STP004 | G24: 20 | I24: MONOVIA INT BR-PRIM PREVEN ELÉTRICA | J24: =LEN(I24) -> 35 | K24: =VLOOKUP(F24,'Cod Planos'!$A:$G,2,FALSE) -> REP PREVENT MANUT SIST-P 3P1 | L24: =VLOOKUP(F24,'Cod Planos'!$A:$G,4,FALSE) -> 3 | M24: =VLOOKUP(F24,'Cod Planos'!$A:$G,5,FALSE) -> PRD | N24: =VLOOKUP(F24,'Cod Planos'!$A:$G,6,FALSE) -> 3 PARADAS | O24: =VLOOKUP(F24,'Cod Planos'!$A:$G,7,FALSE) -> 35 | P24: 4 | Q24: =I24 -> MONOVIA INT BR-PRIM PREVEN ELÉTRICA | R24: CR01
A25: 10384732 | B25: 041 | C25: R55E-041 | D25: P | E25: 0 | F25: URRST3STP005 | G25: 21 | I25: MONOVIA EXT BR-PRIM PREVEN ELÉTRICA | J25: =LEN(I25) -> 35 | K25: =VLOOKUP(F25,'Cod Planos'!$A:$G,2,FALSE) -> REP PREVENT MANUT SIST-P 3P2 | L25: =VLOOKUP(F25,'Cod Planos'!$A:$G,4,FALSE) -> 3 | M25: =VLOOKUP(F25,'Cod Planos'!$A:$G,5,FALSE) -> PRD | N25: =VLOOKUP(F25,'Cod Planos'!$A:$G,6,FALSE) -> 3 PARADAS | O25: =VLOOKUP(F25,'Cod Planos'!$A:$G,7,FALSE) -> 35 | P25: 4 | Q25: =I25 -> MONOVIA EXT BR-PRIM PREVEN ELÉTRICA | R25: CR01
A26: US01-RD-SINT3-SISTP-PRODU-PVQ01-SCT | B26: 041 | C26: R55E-041 | D26: P | E26: 0 | F26: URRST3STP001 | G26: 22 | I26: PENEIRA PVQ1 LIMPEZ PREV ELÉTR | J26: =LEN(I26) -> 31 | K26: =VLOOKUP(F26,'Cod Planos'!$A:$G,2,FALSE) -> REP PREVENT MANUT SIST-P 1P1 | L26: =VLOOKUP(F26,'Cod Planos'!$A:$G,4,FALSE) -> 1 | M26: =VLOOKUP(F26,'Cod Planos'!$A:$G,5,FALSE) -> PRD | N26: =VLOOKUP(F26,'Cod Planos'!$A:$G,6,FALSE) -> PARADA | O26: =VLOOKUP(F26,'Cod Planos'!$A:$G,7,FALSE) -> 100 | P26: 1 | Q26: =I26 -> PENEIRA PVQ1 LIMPEZ PREV ELÉTR | R26: CR01
A27: US01-RD-SINT3-SISTP-PRODU-PVQ01-SAC | B27: 041 | C27: R55E-041 | D27: P | E27: 0 | F27: URRST3STP007 | G27: 23 | I27: PENEIRA PVQ1 PREVENT MOTOR | J27: =LEN(I27) -> 26 | K27: =VLOOKUP(F27,'Cod Planos'!$A:$G,2,FALSE) -> REP PREVENT MANUT SIST-P 6P1 | L27: =VLOOKUP(F27,'Cod Planos'!$A:$G,4,FALSE) -> 6 | M27: =VLOOKUP(F27,'Cod Planos'!$A:$G,5,FALSE) -> PRD | N27: =VLOOKUP(F27,'Cod Planos'!$A:$G,6,FALSE) -> 6 PARADAS | O27: =VLOOKUP(F27,'Cod Planos'!$A:$G,7,FALSE) -> 65 | P27: 4 | Q27: =I27 -> PENEIRA PVQ1 PREVENT MOTOR | R27: CR01
A28: US01-RD-SINT3-SISTP-PRODU-PVQ01-SCT | B28: 041 | C28: R55E-041 | D28: P | E28: 0 | F28: URRST3STP005 | G28: 24 | I28: PENEIRA PVQ1 PREVENT ELÉTRICA | J28: =LEN(I28) -> 29 | K28: =VLOOKUP(F28,'Cod Planos'!$A:$G,2,FALSE) -> REP PREVENT MANUT SIST-P 3P2 | L28: =VLOOKUP(F28,'Cod Planos'!$A:$G,4,FALSE) -> 3 | M28: =VLOOKUP(F28,'Cod Planos'!$A:$G,5,FALSE) -> PRD | N28: =VLOOKUP(F28,'Cod Planos'!$A:$G,6,FALSE) -> 3 PARADAS | O28: =VLOOKUP(F28,'Cod Planos'!$A:$G,7,FALSE) -> 35 | P28: 2 | Q28: =I28 -> PENEIRA PVQ1 PREVENT ELÉTRICA | R28: CR01
A29: 10384734 | B29: 041 | C29: R55E-041 | D29: P | E29: 0 | F29: URRST3STP005 | G29: 25 | I29: MONOVIA PVQ1 PREVENTIVA ELÉTRICA | J29: =LEN(I29) -> 32 | K29: =VLOOKUP(F29,'Cod Planos'!$A:$G,2,FALSE) -> REP PREVENT MANUT SIST-P 3P2 | L29: =VLOOKUP(F29,'Cod Planos'!$A:$G,4,FALSE) -> 3 | M29: =VLOOKUP(F29,'Cod Planos'!$A:$G,5,FALSE) -> PRD | N29: =VLOOKUP(F29,'Cod Planos'!$A:$G,6,FALSE) -> 3 PARADAS | O29: =VLOOKUP(F29,'Cod Planos'!$A:$G,7,FALSE) -> 35 | P29: 2 | Q29: =I29 -> MONOVIA PVQ1 PREVENTIVA ELÉTRICA | R29: CR01
A30: US01-RD-SINT3-SISTP-PRODU-PVQ02-SCT | B30: 041 | C30: R55E-041 | D30: P | E30: 0 | F30: URRST3STP001 | G30: 26 | I30: PENEIRA PVQ2 LIMPEZ PREV ELÉTR | J30: =LEN(I30) -> 31 | K30: =VLOOKUP(F30,'Cod Planos'!$A:$G,2,FALSE) -> REP PREVENT MANUT SIST-P 1P1 | L30: =VLOOKUP(F30,'Cod Planos'!$A:$G,4,FALSE) -> 1 | M30: =VLOOKUP(F30,'Cod Planos'!$A:$G,5,FALSE) -> PRD | N30: =VLOOKUP(F30,'Cod Planos'!$A:$G,6,FALSE) -> PARADA | O30: =VLOOKUP(F30,'Cod Planos'!$A:$G,7,FALSE) -> 100 | P30: 1 | Q30: =I30 -> PENEIRA PVQ2 LIMPEZ PREV ELÉTR | R30: CR01
A31: US01-RD-SINT3-SISTP-PRODU-PVQ02-SAC | B31: 041 | C31: R55E-041 | D31: P | E31: 0 | F31: URRST3STP008 | G31: 27 | I31: PENEIRA PVQ2 PREVENT MOTOR | J31: =LEN(I31) -> 26 | K31: =VLOOKUP(F31,'Cod Planos'!$A:$G,2,FALSE) -> REP PREVENT MANUT SIST-P 6P2 | L31: =VLOOKUP(F31,'Cod Planos'!$A:$G,4,FALSE) -> 6 | M31: =VLOOKUP(F31,'Cod Planos'!$A:$G,5,FALSE) -> PRD | N31: =VLOOKUP(F31,'Cod Planos'!$A:$G,6,FALSE) -> 6 PARADAS | O31: =VLOOKUP(F31,'Cod Planos'!$A:$G,7,FALSE) -> 65 | P31: 4 | Q31: =I31 -> PENEIRA PVQ2 PREVENT MOTOR | R31: CR01
A32: US01-RD-SINT3-SISTP-PRODU-PVQ02-SCT | B32: 041 | C32: R55E-041 | D32: P | E32: 0 | F32: URRST3STP005 | G32: 28 | I32: PENEIRA PVQ2 PREVENT ELÉTRICA | J32: =LEN(I32) -> 29 | K32: =VLOOKUP(F32,'Cod Planos'!$A:$G,2,FALSE) -> REP PREVENT MANUT SIST-P 3P2 | L32: =VLOOKUP(F32,'Cod Planos'!$A:$G,4,FALSE) -> 3 | M32: =VLOOKUP(F32,'Cod Planos'!$A:$G,5,FALSE) -> PRD | N32: =VLOOKUP(F32,'Cod Planos'!$A:$G,6,FALSE) -> 3 PARADAS | O32: =VLOOKUP(F32,'Cod Planos'!$A:$G,7,FALSE) -> 35 | P32: 2 | Q32: =I32 -> PENEIRA PVQ2 PREVENT ELÉTRICA | R32: CR01
A33: 10384736 | B33: 041 | C33: R55E-041 | D33: P | E33: 0 | F33: URRST3STP005 | G33: 29 | I33: MONOVIA PVQ2 PREVENTIVA ELÉTRICA | J33: =LEN(I33) -> 32 | K33: =VLOOKUP(F33,'Cod Planos'!$A:$G,2,FALSE) -> REP PREVENT MANUT SIST-P 3P2 | L33: =VLOOKUP(F33,'Cod Planos'!$A:$G,4,FALSE) -> 3 | M33: =VLOOKUP(F33,'Cod Planos'!$A:$G,5,FALSE) -> PRD | N33: =VLOOKUP(F33,'Cod Planos'!$A:$G,6,FALSE) -> 3 PARADAS | O33: =VLOOKUP(F33,'Cod Planos'!$A:$G,7,FALSE) -> 35 | P33: 4 | Q33: =I33 -> MONOVIA PVQ2 PREVENTIVA ELÉTRICA | R33: CR01
A34: US01-RD-SINT3-SISTP-PRODU-C_SED-SCT | B34: 041 | C34: R55E-041 | D34: P | E34: 0 | F34: URRST3STP005 | G34: 30 | I34: CÂMARAS SEDMENT PREVENTIVA ELÉTRICA | J34: =LEN(I34) -> 35 | K34: =VLOOKUP(F34,'Cod Planos'!$A:$G,2,FALSE) -> REP PREVENT MANUT SIST-P 3P2 | L34: =VLOOKUP(F34,'Cod Planos'!$A:$G,4,FALSE) -> 3 | M34: =VLOOKUP(F34,'Cod Planos'!$A:$G,5,FALSE) -> PRD | N34: =VLOOKUP(F34,'Cod Planos'!$A:$G,6,FALSE) -> 3 PARADAS | O34: =VLOOKUP(F34,'Cod Planos'!$A:$G,7,FALSE) -> 35 | P34: 3 | Q34: =I34 -> CÂMARAS SEDMENT PREVENTIVA ELÉTRICA | R34: CR01
A35: US01-RD-SINT3-SISTP-PRODU-BR_PR-SRF | B35: 041 | C35: R55E-041 | D35: P | E35: 0 | F35: URRST3STP001 | G35: 31 | I35: BOMB REF BRIT/FOR LIMPEZ PREV ELÉTR | J35: =LEN(I35) -> 35 | K35: =VLOOKUP(F35,'Cod Planos'!$A:$G,2,FALSE) -> REP PREVENT MANUT SIST-P 1P1 | L35: =VLOOKUP(F35,'Cod Planos'!$A:$G,4,FALSE) -> 1 | M35: =VLOOKUP(F35,'Cod Planos'!$A:$G,5,FALSE) -> PRD | N35: =VLOOKUP(F35,'Cod Planos'!$A:$G,6,FALSE) -> PARADA | O35: =VLOOKUP(F35,'Cod Planos'!$A:$G,7,FALSE) -> 100 | P35: 1 | Q35: =I35 -> BOMB REF BRIT/FOR LIMPEZ PREV ELÉTR | R35: CR01
A36: US01-RD-SINT3-SISTP-PRODU-BR_PR-SRF | B36: 041 | C36: R55E-041 | D36: P | E36: 0 | F36: URRST3STP008 | G36: 32 | I36: BOMBAS REF BRIT/FOR PREVENT MOTOR | J36: =LEN(I36) -> 33 | K36: =VLOOKUP(F36,'Cod Planos'!$A:$G,2,FALSE) -> REP PREVENT MANUT SIST-P 6P2 | L36: =VLOOKUP(F36,'Cod Planos'!$A:$G,4,FALSE) -> 6 | M36: =VLOOKUP(F36,'Cod Planos'!$A:$G,5,FALSE) -> PRD | N36: =VLOOKUP(F36,'Cod Planos'!$A:$G,6,FALSE) -> 6 PARADAS | O36: =VLOOKUP(F36,'Cod Planos'!$A:$G,7,FALSE) -> 65 | P36: 4 | Q36: =I36 -> BOMBAS REF BRIT/FOR PREVENT MOTOR | R36: CR01
A37: US01-RD-SINT3-SISTP-PREPA-FORNO-SCB | B37: 041 | C37: R55E-041 | D37: P | E37: 0 | F37: URRST3STP001 | G37: 33 | I37: SOPRAD FORNO IGNI LIMPEZ PREV ELÉTR | J37: =LEN(I37) -> 35 | K37: =VLOOKUP(F37,'Cod Planos'!$A:$G,2,FALSE) -> REP PREVENT MANUT SIST-P 1P1 | L37: =VLOOKUP(F37,'Cod Planos'!$A:$G,4,FALSE) -> 1 | M37: =VLOOKUP(F37,'Cod Planos'!$A:$G,5,FALSE) -> PRD | N37: =VLOOKUP(F37,'Cod Planos'!$A:$G,6,FALSE) -> PARADA | O37: =VLOOKUP(F37,'Cod Planos'!$A:$G,7,FALSE) -> 100 | P37: 1 | Q37: =I37 -> SOPRAD FORNO IGNI LIMPEZ PREV ELÉTR | R37: CR01
A38: 10380852 | B38: 041 | C38: R55E-041 | D38: P | E38: 0 | F38: URRST3STP008 | G38: 34 | I38: SOPRAD FORNO IGNI PREVENT MOTOR | J38: =LEN(I38) -> 31 | K38: =VLOOKUP(F38,'Cod Planos'!$A:$G,2,FALSE) -> REP PREVENT MANUT SIST-P 6P2 | L38: =VLOOKUP(F38,'Cod Planos'!$A:$G,4,FALSE) -> 6 | M38: =VLOOKUP(F38,'Cod Planos'!$A:$G,5,FALSE) -> PRD | N38: =VLOOKUP(F38,'Cod Planos'!$A:$G,6,FALSE) -> 6 PARADAS | O38: =VLOOKUP(F38,'Cod Planos'!$A:$G,7,FALSE) -> 65 | P38: 2 | Q38: =I38 -> SOPRAD FORNO IGNI PREVENT MOTOR | R38: CR01
A39: US01-RD-SINT3-SISTP-PREPA-FORNO-SCB | B39: 041 | C39: R55E-041 | D39: P | E39: 0 | F39: URRST3STP005 | G39: 35 | I39: SOPRAD FORNO IGNI PREVENT ELÉTR | J39: =LEN(I39) -> 31 | K39: =VLOOKUP(F39,'Cod Planos'!$A:$G,2,FALSE) -> REP PREVENT MANUT SIST-P 3P2 | L39: =VLOOKUP(F39,'Cod Planos'!$A:$G,4,FALSE) -> 3 | M39: =VLOOKUP(F39,'Cod Planos'!$A:$G,5,FALSE) -> PRD | N39: =VLOOKUP(F39,'Cod Planos'!$A:$G,6,FALSE) -> 3 PARADAS | O39: =VLOOKUP(F39,'Cod Planos'!$A:$G,7,FALSE) -> 35 | P39: 2 | Q39: =I39 -> SOPRAD FORNO IGNI PREVENT ELÉTR | R39: CR01
A40: US01-RD-SINT3-SISTF-TRANS-F_209-SCT | B40: 041 | C40: R55E-041 | D40: P | E40: 0 | F40: URRST3STF005 | G40: 36 | I40: F209 MANUT PREVENTIVA ELÉTRICA | J40: =LEN(I40) -> 31 | K40: =VLOOKUP(F40,'Cod Planos'!$A:$G,2,FALSE) -> REP PREVENT MANUT SIST-F 3P2 | L40: =VLOOKUP(F40,'Cod Planos'!$A:$G,4,FALSE) -> 3 | M40: =VLOOKUP(F40,'Cod Planos'!$A:$G,5,FALSE) -> PRD | N40: =VLOOKUP(F40,'Cod Planos'!$A:$G,6,FALSE) -> 3 PARADAS | O40: =VLOOKUP(F40,'Cod Planos'!$A:$G,7,FALSE) -> 35 | P40: 2 | Q40: =I40 -> F209 MANUT PREVENTIVA ELÉTRICA | R40: CR01
A41: 10367656 | B41: 041 | C41: R55E-041 | D41: P | E41: 0 | F41: URRST3STP008 | G41: 37 | I41: F209 PREVENTIVA MOTOR ELÉTRICO | J41: =LEN(I41) -> 30 | K41: =VLOOKUP(F41,'Cod Planos'!$A:$G,2,FALSE) -> REP PREVENT MANUT SIST-P 6P2 | L41: =VLOOKUP(F41,'Cod Planos'!$A:$G,4,FALSE) -> 6 | M41: =VLOOKUP(F41,'Cod Planos'!$A:$G,5,FALSE) -> PRD | N41: =VLOOKUP(F41,'Cod Planos'!$A:$G,6,FALSE) -> 6 PARADAS | O41: =VLOOKUP(F41,'Cod Planos'!$A:$G,7,FALSE) -> 65 | P41: 2 | Q41: =I41 -> F209 PREVENTIVA MOTOR ELÉTRICO | R41: CR01
A42: US01-RD-SINT3-SISTF-TRANS-F_209-SCT | B42: 041 | C42: R55E-041 | D42: P | E42: 0 | F42: URRST3STF001 | G42: 38 | I42: F209 LIMPEZA PREVENTIVA ELÉTRICA | J42: =LEN(I42) -> 33 | K42: =VLOOKUP(F42,'Cod Planos'!$A:$G,2,FALSE) -> REP PREVENT MANUT SIST-F 1P1 | L42: =VLOOKUP(F42,'Cod Planos'!$A:$G,4,FALSE) -> 1 | M42: =VLOOKUP(F42,'Cod Planos'!$A:$G,5,FALSE) -> PRD | N42: =VLOOKUP(F42,'Cod Planos'!$A:$G,6,FALSE) -> PARADA | O42: =VLOOKUP(F42,'Cod Planos'!$A:$G,7,FALSE) -> 100 | P42: 1 | Q42: =I42 -> F209 LIMPEZA PREVENTIVA ELÉTRICA | R42: CR01
...

Sheet SÍNTESE DE CARACT - INSPEÇÃO
A1: SÍNTESE DE CARACTERÍTICAS
A2: Identificador | B2: Caracteristica mestre cont QUANTITA/ QUALITAT | C2: ITENS DE INSPEÇÃO | D2: MÉTODO | E2: CASAS DECIMAIS | F2: UNIDADE DE MEDIDA | G2: VALOR REFERÊNCIA | H2: LIMITE INFERIOR | I2: VALOR SUPERIOR
A3: 1 | B3: QUALITAT | C3: apagar linha | D3: MANOM | E3: 2 | F3: l/min | G3: 60 | H3: 50 | I3: 65
A4: 2 | B4: QUALITAT | C4: apagar linha | D4: VISUAL

Sheet OPERAÇÕES - REPARO
A1: Identificador | B1: Local de Instalação | C1: Operação | D1: Sub Operação | E1: Centro de trabalho | F1: Texto breve | G1: QTD CARACTERES | H1: UNIDADE MEDI | I1: EFETIVO | J1: HORAS
A2: 1 | B2: US01-RD-SINT3-SISTP-PRODU-GNMS3-SCT | C2: 0010 | E2: R55E-041 | F2: CAVALETE GN LIMPEZA PREVENTIVA ELÉTRICA | G2: =LEN(F2) -> 39 | H2: H | I2: 2 | J2: 1
A3: 1 | B3: US01-RD-SINT3-SISTP-PRODU-GNMS3-SCT | C3: 0010 | D3: 0010 | E3: R55E-041 | F3: MECÂNICO SOLDADOR OU SOLDADOR | G3: =LEN(F3) -> 29 | H3: H
A4: 1 | B4: US01-RD-SINT3-SISTP-PRODU-GNMS3-SCT | C4: 0010 | D4: 0011 | E4: R55E-041 | F4: SUPERVISOR OU LIDER DE GRUPO | G4: =LEN(F4) -> 28 | H4: H
A5: 1 | B5: US01-RD-SINT3-SISTP-PRODU-GNMS3-SCT | C5: 0010 | D5: 0012 | E5: R55E-041 | F5: RECOMENDAÇÕES SEGURANÇA E MEIO AMBIENTE | G5: =LEN(F5) -> 39 | H5: H
A6: 1 | B6: US01-RD-SINT3-SISTP-PRODU-GNMS3-SCT | C6: 0010 | D6: 0013 | E6: R55E-041 | F6: ATIVIDADES DE PREPARAÇÃO | G6: =LEN(F6) -> 24 | H6: H
A7: 1 | B7: US01-RD-SINT3-SISTP-PRODU-GNMS3-SCT | C7: 0010 | D7: 0014 | E7: R55E-041 | F7: DOCUMENTOS TÉCNICOS | G7: =LEN(F7) -> 19 | H7: H
A8: 1 | B8: US01-RD-SINT3-SISTP-PRODU-GNMS3-SCT | C8: 0020 | E8: R55E-041 | F8: LIMPEZA PREVENTIVA CAVALETE DE GN | G8: =LEN(F8) -> 33 | H8: H
A9: 2 | B9: US01-RD-SINT3-SISTP-ARMAZ-TRMIS-SCT | C9: 0010 | E9: R55E-041 | F9: COMPORTA TREMONHA PREVENTIVA ELÉTRICA | G9: =LEN(F9) -> 37 | H9: H | I9: 2 | J9: 2
A10: 2 | B10: US01-RD-SINT3-SISTP-ARMAZ-TRMIS-SCT | C10: 0010 | D10: 0010 | E10: R55E-041 | F10: MECÂNICO SOLDADOR OU SOLDADOR | G10: =LEN(F10) -> 29 | H10: H
A11: 2 | B11: US01-RD-SINT3-SISTP-ARMAZ-TRMIS-SCT | C11: 0010 | D11: 0011 | E11: R55E-041 | F11: SUPERVISOR OU LIDER DE GRUPO | G11: =LEN(F11) -> 28 | H11: H
A12: 2 | B12: US01-RD-SINT3-SISTP-ARMAZ-TRMIS-SCT | C12: 0010 | D12: 0012 | E12: R55E-041 | F12: RECOMENDAÇÕES SEGURANÇA E MEIO AMBIENTE | G12: =LEN(F12) -> 39 | H12: H
A13: 2 | B13: US01-RD-SINT3-SISTP-ARMAZ-TRMIS-SCT | C13: 0010 | D13: 0013 | E13: R55E-041 | F13: ATIVIDADES DE PREPARAÇÃO | G13: =LEN(F13) -> 24 | H13: H
A14: 2 | B14: US01-RD-SINT3-SISTP-ARMAZ-TRMIS-SCT | C14: 0010 | D14: 0014 | E14: R55E-041 | F14: DOCUMENTOS TÉCNICOS | G14: =LEN(F14) -> 19 | H14: H
A15: 2 | B15: US01-RD-SINT3-SISTP-ARMAZ-TRMIS-SCT | C15: 0020 | E15: R55E-041 | F15: MANUT PREVENTIVA SENSORIAMENTO | G15: =LEN(F15) -> 30 | H15: H
A16: 3 | B16: US01-RD-SINT3-SISTP-ARMAZ-TRMIS-SCT | C16: 0010 | E16: R55E-041 | F16: COMPORTA TREMONHA LIMPEZA PREV ELÉTRICA | G16: =LEN(F16) -> 39 | H16: H | I16: 2 | J16: 1
A17: 3 | B17: US01-RD-SINT3-SISTP-ARMAZ-TRMIS-SCT | C17: 0010 | D17: 0010 | E17: R55E-041 | F17: MECÂNICO SOLDADOR OU SOLDADOR | G17: =LEN(F17) -> 29 | H17: H
A18: 3 | B18: US01-RD-SINT3-SISTP-ARMAZ-TRMIS-SCT | C18: 0010 | D18: 0011 | E18: R55E-041 | F18: SUPERVISOR OU LIDER DE GRUPO | G18: =LEN(F18) -> 28 | H18: H
A19: 3 | B19: US01-RD-SINT3-SISTP-ARMAZ-TRMIS-SCT | C19: 0010 | D19: 0012 | E19: R55E-041 | F19: RECOMENDAÇÕES SEGURANÇA E MEIO AMBIENTE | G19: =LEN(F19) -> 39 | H19: H
A20: 3 | B20: US01-RD-SINT3-SISTP-ARMAZ-TRMIS-SCT | C20: 0010 | D20: 0013 | E20: R55E-041 | F20: ATIVIDADES DE PREPARAÇÃO | G20: =LEN(F20) -> 24 | H20: H
A21: 3 | B21: US01-RD-SINT3-SISTP-ARMAZ-TRMIS-SCT | C21: 0010 | D21: 0014 | E21: R55E-041 | F21: DOCUMENTOS TÉCNICOS | G21: =LEN(F21) -> 19 | H21: H
A22: 3 | B22: US01-RD-SINT3-SISTP-ARMAZ-TRMIS-SCT | C22: 0020 | E22: R55E-041 | F22: LIMPEZA PREVENTIVA SENSORIAMENTO | G22: =LEN(F22) -> 32 | H22: H
A23: 3 | B23: US01-RD-SINT3-SISTP-ARMAZ-TRMIS-SCT | C23: 0030 | E23: R55E-041 | F23: LIMPEZA PREVENTIVA MOTOR ELÉTRICO | G23: =LEN(F23) -> 33 | H23: H
A24: 4 | B24: 10380837 | C24: 0010 | E24: R55E-041 | F24: COMPORTA TREMONHA MOTOR ELÉTRICO | G24: =LEN(F24) -> 32 | H24: H | I24: 2 | J24: 2
A25: 4 | B25: 10380837 | C25: 0010 | D25: 0010 | E25: R55E-041 | F25: MECÂNICO SOLDADOR OU SOLDADOR | G25: =LEN(F25) -> 29 | H25: H
A26: 4 | B26: 10380837 | C26: 0010 | D26: 0011 | E26: R55E-041 | F26: SUPERVISOR OU LIDER DE GRUPO | G26: =LEN(F26) -> 28 | H26: H
A27: 4 | B27: 10380837 | C27: 0010 | D27: 0012 | E27: R55E-041 | F27: RECOMENDAÇÕES SEGURANÇA E MEIO AMBIENTE | G27: =LEN(F27) -> 39 | H27: H
A28: 4 | B28: 10380837 | C28: 0010 | D28: 0013 | E28: R55E-041 | F28: ATIVIDADES DE PREPARAÇÃO | G28: =LEN(F28) -> 24 | H28: H
A29: 4 | B29: 10380837 | C29: 0010 | D29: 0014 | E29: R55E-041 | F29: DOCUMENTOS TÉCNICOS | G29: =LEN(F29) -> 19 | H29: H
A30: 4 | B30: 10380837 | C30: 0020 | E30: R55E-041 | F30: PREVENT MOTOR ACIONAMENTO COMPORTA PRINC | G30: =LEN(F30) -> 40 | H30: H
A31: 5 | B31: 10384772 | C31: 0010 | E31: R55E-041 | F31: DETECTOR CAMADAS PREVENTIVA ELÉTRICA | G31: =LEN(F31) -> 36 | H31: H | I31: 2 | J31: 4
A32: 5 | B32: 10384772 | C32: 0010 | D32: 0010 | E32: R55E-041 | F32: MECÂNICO SOLDADOR OU SOLDADOR | G32: =LEN(F32) -> 29 | H32: H
A33: 5 | B33: 10384772 | C33: 0010 | D33: 0011 | E33: R55E-041 | F33: SUPERVISOR OU LIDER DE GRUPO | G33: =LEN(F33) -> 28 | H33: H
A34: 5 | B34: 10384772 | C34: 0010 | D34: 0012 | E34: R55E-041 | F34: RECOMENDAÇÕES SEGURANÇA E MEIO AMBIENTE | G34: =LEN(F34) -> 39 | H34: H
A35: 5 | B35: 10384772 | C35: 0010 | D35: 0013 | E35: R55E-041 | F35: ATIVIDADES DE PREPARAÇÃO | G35: =LEN(F35) -> 24 | H35: H
A36: 5 | B36: 10384772 | C36: 0010 | D36: 0014 | E36: R55E-041 | F36: DOCUMENTOS TÉCNICOS | G36: =LEN(F36) -> 19 | H36: H
A37: 5 | B37: 10384772 | C37: 0020 | E37: R55E-041 | F37: MANUT PREVENTIVA DETECTOR DE CAMADAS | G37: =LEN(F37) -> 36 | H37: H
A38: 6 | B38: US01-RD-SINT3-SISTP-PREPA-R_ALI-SCT | C38: 0010 | E38: R55E-041 | F38: ROLO ALIMENTADOR PREVENTIVA ELÉTRICA | G38: =LEN(F38) -> 36 | H38: H | I38: 2 | J38: 2
A39: 6 | B39: US01-RD-SINT3-SISTP-PREPA-R_ALI-SCT | C39: 0010 | D39: 0010 | E39: R55E-041 | F39: MECÂNICO SOLDADOR OU SOLDADOR | G39: =LEN(F39) -> 29 | H39: H
A40: 6 | B40: US01-RD-SINT3-SISTP-PREPA-R_ALI-SCT | C40: 0010 | D40: 0011 | E40: R55E-041 | F40: SUPERVISOR OU LIDER DE GRUPO | G40: =LEN(F40) -> 28 | H40: H
...

Sheet TEXTO LONGO REPARO.CSV
B1: Identificador | C1: Local de Instalação | D1: cod. Equipamento | E1: Geral | F1: GrpLisTar. | G1: NumGrpRot | H1: OPER | I1: SUB OPER | J1: Descrição da operação
B2: 1 | C2: US01-RD-SINT3-SISTP-PRODU-GNMS3-SCT | H2: 0010 | J2: CAVALETE GN LIMPEZA PREVENTIVA ELÉTRICA
B3: 1 | C3: US01-RD-SINT3-SISTP-PRODU-GNMS3-SCT | H3: 0010 | I3: 0010 | J3: NÃO SE APLICA
B4: 1 | C4: US01-RD-SINT3-SISTP-PRODU-GNMS3-SCT | H4: 0010 | I4: 0011 | J4: NÃO SE APLICA
B5: 1 | C5: US01-RD-SINT3-SISTP-PRODU-GNMS3-SCT | H5: 0010 | I5: 0012 | J5: 1. ABERTURA DA PPT: 1.1. A PPT DEVERÁ SER ABERTA E LIBERADA PELA EQUIPE DA OPERAÇÃO NO QUINTO PISO DA MÁQUINA DE SINTER 3 2.APRESENTAÇÃO DA EQUIPE: 2.1. LOCAL DE APRESENTAÇÃO: SALA DA INSPEÇÃO 2.2. TÉCNICO RESPONSÁVEL E TELEFONE ESTÁ NO CABEÇALHO DA ORDEM NO CAMPO (GPM). 3. TESTE DE EFICÁCIA 3.1. CONTROLADOR ELÉTRICA: CONFIRMAÇÃO DE AUSÊNCIA DE TENSÃO NO CIRCUITO DE FORÇA DO EQUIPAMENTO 3.2. CONTROLADOR MECÂNICA: NÃO SE APLICA 3.3. OPERAÇÃO: TESTE DE TENTATIVA DE COMANDO DO EQUIPAMENTO 3.4. O EXECUTANTE DEVE ACOMPANHAR O RESPONSÁVEL DA OPERAÇÃO DURANTE O TESTE DE EFICÁCIA DE BLOQUEIO NA ÁREA OPERACIONAL. 3. EPIS E EPCS ESPECIFICOS DA ÁREA - MÁSCARA CONTRA PÓ PFF1 - LUVAS. - ÓCULOS HÉRMETICO - DETECTOR MULTI-GÁS. 4. EPIS E EPCS ESPECIFICOS DA ATIVIDADE - ROUPAS ANTICHAMAS NR10. 5. RISCOS GERAIS DA ÁREA: 5.1 QUEDA HUMANA - PISO IRREGULAR, ESCORREGADIO COM DESNÍVEIS E ACÚMULO DE MATERIAIS. UTILIZE SEMPRE OS CORRIMÃOS AO SUBIR E DESCER ESCADAS E AO SE DESLOCAR SOBRE PASSARELAS - ANTES DE ACESSAR, AVALIE BEM O LOCAL PARA QUE NÃO SEJA SURPREENDIDO POR BURACOS, CHAPAS DE PISO SOLTAS, CORRIMÃOS AVARIADOS E DESNÍVEIS DE PISO, CASO SUA ROTA NÃO ESTEJA EM CONDIÇÕES SEGURAS, USE OUTRA ROTA QUE SEJA SEGURA E COMUNIQUE AO RESPONSAVEL PARA RESOLUÇÃO DA ANORMALIDADE. - NÃO ACESSAR PASSARELAS COM ACÚMULO DE MATERIAL, AO IDENTIFICAR SITUAÇÕES SEMELHANTES, IMEDIATAMENTE ISOLAR O LOCAL. 5.2. QUEDA DE MATERIAIS E FERRAMENTAS. - NÃO TRANSITAR SOB LOCAIS DE ATIVIDADES SOBREPOSTAS - NOS TRABALHOS EM ALTURA REALIZAR AMARRAÇÃO DAS FERRAMENTAS. - ARMAZENAR FERRAMENTAS DE PEQUENO PORTE EM RECIPIENTES ADEQUADOS, ELIMINANDO O RISCO DE QUEDA NA PARTE INFERIOR. - AO TRANSITAR SOB TRANSPORTADORES DE CORREIA, OLHAR PARA CIMA E VERIFICAR A EXISTÊNCIA DO RISCO DE QUEDA DE PEÇAS E/OU MATERIAL COMPACTADO NA ESTRUTURA. OBSERVE SE ELA TEM PROTEÇÕES ABAIXO CONTRA QUEDA DE MATERIAL, CASO NAO TENHA PROCURE OUTRA ROTA. 5.3. ATROPELAMENTO - RISCO DE ATROPELAMENTO POR MÁQUINAS DE LIMPEZA (RETROESCAVADEIRA, BOBCAT E CAMINHÕES) ENTRE OS TRANSPORTADORES - RISCO DE ATROPELAMENTO POR VEÍCULO AO TRANSITAR PELAS RUAS. - PARAR, OLHAR E ESCUTAR ANTES DE TRANSITAR EM LOCAIS COM PRESENÇA DE VEICULOS MOTORIZADOS, SE NECESSARIO UTILIZE OUTRA ROTA PARA DESLOCAMENTO. - NÃO PASSAR EMBAIXO DE MATERIAIS SUSPENSOS POR GUINDASTE, PONTE ROLANTE E TALHAS ELÉTRICAS. - NÃO ULTRAPASSAR ÁREAS ISOLADAS POR CORRENTES, FITAS E/OU CERQUITES, CASO SEJA NECESSÁRIO O ACESSO PEDIR AUTORIZAÇÃO A UM RESPONSÁVEL PELA ATIVIDADE. - NÃO FICAR POSICIONADO NO RAIO DE AÇÃO DA PARTE TRASEIRA DE MÁQUINAS E EQUIPAMENTOS, O MOTORISTA NÃO TEM VISÃO AMPLA EM MANOBRAS EM MARCHA RÉ. 5.4. PARTICULADOS EM SUSPENÇÃO (POEIRA) - USAR MÁSCARA CONTRA POEIRA FIXADA AO ROSTO DURANTE TODO TEMPO QUE ESTIVER A ÁREA COM EXPOSIÇÃO AO RISCO. - OBRIGATÓRIO A UTILIZAÇÃO DE MÁSCARA DE PROTEÇÃO CONTRA POEIRAS EM TODA A ÁREA DE SINTERIZAÇÃO E MATÉRIAS-PRIMAS. 5.5. PRENSAMENTO/ESMAGAMENTO - A ÁREA POSSUI VÁRIOS TRANSPORTADORES DE CORREIA COM PARTES MÓVEIS QUE PODEM GERAR PRENSAMENTO DE MEMBROS E/OU ESMAGAMENTO. NÃO SE APROXIME DE PARTES MÓVEIS E SÓ ACESSE OS TRANSPORTADORES QUE POSSUEM GRADES DE PROTEÇÃO CONFORME NR12, OU COM O EQUIPAMENTO PARADO E BLOQUEADO, CONFORME NORMA CORPORATIVA – NCSEGGE0002. 5.6. INTOXICAÇÃO POR GÁS - UTILIZAR DETECTOR DE GÁS AO TRABALHAR NO 5° PISO DA MÁQUINA. RISCO DE VAZAMENTO DE GÁS PRÓXIMO À CAMARA DE COMBUSTÃO. 6. RECOMENDAÇÃO DE MEIO AMBIENTE - REALIZAR A SEPARAÇÃO E DESCARTE DE RESTOS DE MANUTENÇÃO, INCLUINDO PEÇAS METÁLICAS, MADEIRA, BORRACHA E OUTROS NA BAIA DE DESCARTE DA OFICINA 410. - REALIZAR DESCARTE DE MATERIAIS RECICLÁVEIS NOS TAMBORES COLORIDOS CONFORME TIPO DE MATERIAL NA OFICINA 410.
B6: 1 | C6: US01-RD-SINT3-SISTP-PRODU-GNMS3-SCT | H6: 0010 | I6: 0013 | J6: NÃO SE APLICA
B7: 1 | C7: US01-RD-SINT3-SISTP-PRODU-GNMS3-SCT | H7: 0010 | I7: 0014 | J7: 1. DESENGRIPANTE GA LUB (FDS SCFISPQ1093) 2. SILICONE LOCTITE SUPERFLEX 595 (FDS SCFISPM0896) 3. COMPOSTO DESENGRAXANTE SOLVENTE (FDS SCFISPI3551) 4. COMPOSTO LIMPEZA DE CONTATOS ELÉTRICOS (FDS SCFISPI3599)
B8: 1 | C8: US01-RD-SINT3-SISTP-PRODU-GNMS3-SCT | H8: 0020 | J8: 1-LIMPEZA DAS ELETROVÁLVULAS DE GÁS 1.1 ACESSAR A PARTE INTERNA DO SISTEMA DE GÁS DO FORNO À COMBUSTÃO 1.2 REALIZAR LIMPEZA SUPERFICIAL DE TODAS AS VÁLVULAS SOLENOIDER, VÁLVULAS SHUTOFF, VÁLVULAS PILOTO, PRESSOSTATOS E ELETROVÁLVULAS DE CONTROLE DE GÁS, UTILIZANDO SOPRADOR ELÉTRICO, TOALHAS DE PANO E PRODUTO DESENGRAXANTE. 1.3 AVALIAR FISICAMENTE SE EXISTE ALGUMA VÁLVULA OU COMPONENTES ELÉTRICO COM ALGUM TIPO DE DANO SUPERFICIAL (QUEBRA, TRINCA, FALTA DE PARAFUSOS OU QUEIMA VISÍVEL). REPASSE AO TÉCNICO RESPONSÁVEL O QUE FOR ENCONTRADO DE ANORMALIDADE. 1.4 CONFERIR REAPERTO E FIXAÇÃO DOS CONECTORES (PLUGUES) DAS VÁLVULAS E PRESSOSTATOS, UTILIZANDO CHAVES DE FENTA E PHILLIPS. 1.5 CONFERIR REAPERTO DOS PARAFUSOS DE FIXAÇÃO DAS TAMPAS DAS CAIXAS DE LIGAÇÃO DAS VÁLVULAS CONTROLADORAS E SHUTOFF. ( )EXECUTADO ( )NÃO EXECUTADO ------------------------------------------------------------- 2.LIMPEZA E ORGANIZAÇÃO DOS CABOS DAS ELETROVÁLVULAS 2.1 ACESSAR A PARTE INTERNA DO SISTEMA DE GÁS DO FORNO À COMBUSTÃO 2.2 REALIZAR LIMPEZA SUPERFICIAL DE CABOS ELÉTRICOS DE ALIMENTAÇÃO E COMANDO DAS VÁLVULAS DE GÁS, UTILIZANDO TOALHAS DE PANO E PRODUTO DESENGRAXANTE. 2.3 ORGANIZAR OS CABOS, FIXANDO-OS COM FITAS SERRILHADAS. ( )EXECUTADO ( )NÃO EXECUTADO ------------------------------------------------------------- RECOMENDAÇÕES DE SEGURANÇA ESPECÍFICAS DAS ATIVIDADES 1. RISCO DE PROJEÇÃO. - NAO DIRECIONAR AR COMPRIMIDO PARA O CORPO, CASO A ATIVIDADE GERE MUITO MATERIAL PARTICULADO SUSPENSO DEVIDO O USO DE SOPRADOR ELÉTRICO/AR COMPRIMIDO, UTILIZAR ÓCULOS HERMÉTICO. 2- QUEDA HUMANA - LOCAL COM TUBULAÇÕES E ESTRUTURAS BAIXAS GERANDO RISCO DE QUEDA. AO REALIZAR ATIVIDADE, APOIAR-SE NA ESTRUTURA LATERAL DA GRADE AO PASSAR SOBRE TUBULAÇÕES PRÓXIMAS AO PISO. ---------------------------------------------------------------- EXECUTANTES DECLARO QUE LI E COMPREENDI AS ATIVIDADES E AS RECOMENDAÇÕES DE SEGURANÇA DA OM. NOME________________________ REGISTRO____________________ ASSINATURA__________________ NOME________________________ REGISTRO____________________ ASSINATURA__________________ NOME________________________ REGISTRO____________________ ASSINATURA__________________ NOME________________________ REGISTRO____________________ ASSINATURA__________________ NOME________________________ REGISTRO____________________ ASSINATURA__________________
B9: 2 | C9: US01-RD-SINT3-SISTP-ARMAZ-TRMIS-SCT | H9: 0010 | J9: COMPORTA TREMONHA PREVENTIVA ELÉTRICA
B10: 2 | C10: US01-RD-SINT3-SISTP-ARMAZ-TRMIS-SCT | H10: 0010 | I10: 0010 | J10: NÃO SE APLICA
B11: 2 | C11: US01-RD-SINT3-SISTP-ARMAZ-TRMIS-SCT | H11: 0010 | I11: 0011 | J11: NÃO SE APLICA
B12: 2 | C12: US01-RD-SINT3-SISTP-ARMAZ-TRMIS-SCT | H12: 0010 | I12: 0012 | J12: 1. ABERTURA DA PPT: 1.1. A PPT DEVERÁ SER ABERTA E LIBERADA PELA EQUIPE DA OPERAÇÃO NO QUINTO PISO DA MÁQUINA DE SINTER 3 2.APRESENTAÇÃO DA EQUIPE: 2.1. LOCAL DE APRESENTAÇÃO: SALA DA INSPEÇÃO 2.2. TÉCNICO RESPONSÁVEL E TELEFONE ESTÁ NO CABEÇALHO DA ORDEM NO CAMPO (GPM). 3. TESTE DE EFICÁCIA 3.1. CONTROLADOR ELÉTRICA: CONFIRMAÇÃO DE AUSÊNCIA DE TENSÃO NO CIRCUITO DE FORÇA DO EQUIPAMENTO 3.2. CONTROLADOR MECÂNICA: NÃO SE APLICA 3.3. OPERAÇÃO: TESTE DE TENTATIVA DE COMANDO DO EQUIPAMENTO 3.4. O EXECUTANTE DEVE ACOMPANHAR O RESPONSÁVEL DA OPERAÇÃO DURANTE O TESTE DE EFICÁCIA DE BLOQUEIO NA ÁREA OPERACIONAL. 3. EPIS E EPCS ESPECIFICOS DA ÁREA - MÁSCARA CONTRA PÓ PFF1 - LUVAS. - ÓCULOS HÉRMETICO - DETECTOR MULTI-GÁS. 4. EPIS E EPCS ESPECIFICOS DA ATIVIDADE - ROUPAS ANTICHAMAS NR10. 5. RISCOS GERAIS DA ÁREA: 5.1 QUEDA HUMANA - PISO IRREGULAR, ESCORREGADIO COM DESNÍVEIS E ACÚMULO DE MATERIAIS. UTILIZE SEMPRE OS CORRIMÃOS AO SUBIR E DESCER ESCADAS E AO SE DESLOCAR SOBRE PASSARELAS - ANTES DE ACESSAR, AVALIE BEM O LOCAL PARA QUE NÃO SEJA SURPREENDIDO POR BURACOS, CHAPAS DE PISO SOLTAS, CORRIMÃOS AVARIADOS E DESNÍVEIS DE PISO, CASO SUA ROTA NÃO ESTEJA EM CONDIÇÕES SEGURAS, USE OUTRA ROTA QUE SEJA SEGURA E COMUNIQUE AO RESPONSAVEL PARA RESOLUÇÃO DA ANORMALIDADE. - NÃO ACESSAR PASSARELAS COM ACÚMULO DE MATERIAL, AO IDENTIFICAR SITUAÇÕES SEMELHANTES, IMEDIATAMENTE ISOLAR O LOCAL. 5.2. QUEDA DE MATERIAIS E FERRAMENTAS. - NÃO TRANSITAR SOB LOCAIS DE ATIVIDADES SOBREPOSTAS - NOS TRABALHOS EM ALTURA REALIZAR AMARRAÇÃO DAS FERRAMENTAS. - ARMAZENAR FERRAMENTAS DE PEQUENO PORTE EM RECIPIENTES ADEQUADOS, ELIMINANDO O RISCO DE QUEDA NA PARTE INFERIOR. - AO TRANSITAR SOB TRANSPORTADORES DE CORREIA, OLHAR PARA CIMA E VERIFICAR A EXISTÊNCIA DO RISCO DE QUEDA DE PEÇAS E/OU MATERIAL COMPACTADO NA ESTRUTURA. OBSERVE SE ELA TEM PROTEÇÕES ABAIXO CONTRA QUEDA DE MATERIAL, CASO NAO TENHA PROCURE OUTRA ROTA. 5.3. ATROPELAMENTO - RISCO DE ATROPELAMENTO POR MÁQUINAS DE LIMPEZA (RETROESCAVADEIRA, BOBCAT E CAMINHÕES) ENTRE OS TRANSPORTADORES - RISCO DE ATROPELAMENTO POR VEÍCULO AO TRANSITAR PELAS RUAS. - PARAR, OLHAR E ESCUTAR ANTES DE TRANSITAR EM LOCAIS COM PRESENÇA DE VEICULOS MOTORIZADOS, SE NECESSARIO UTILIZE OUTRA ROTA PARA DESLOCAMENTO. - NÃO PASSAR EMBAIXO DE MATERIAIS SUSPENSOS POR GUINDASTE, PONTE ROLANTE E TALHAS ELÉTRICAS. - NÃO ULTRAPASSAR ÁREAS ISOLADAS POR CORRENTES, FITAS E/OU CERQUITES, CASO SEJA NECESSÁRIO O ACESSO PEDIR AUTORIZAÇÃO A UM RESPONSÁVEL PELA ATIVIDADE. - NÃO FICAR POSICIONADO NO RAIO DE AÇÃO DA PARTE TRASEIRA DE MÁQUINAS E EQUIPAMENTOS, O MOTORISTA NÃO TEM VISÃO AMPLA EM MANOBRAS EM MARCHA RÉ. 5.4. PARTICULADOS EM SUSPENÇÃO (POEIRA) - USAR MÁSCARA CONTRA POEIRA FIXADA AO ROSTO DURANTE TODO TEMPO QUE ESTIVER A ÁREA COM EXPOSIÇÃO AO RISCO. - OBRIGATÓRIO A UTILIZAÇÃO DE MÁSCARA DE PROTEÇÃO CONTRA POEIRAS EM TODA A ÁREA DE SINTERIZAÇÃO E MATÉRIAS-PRIMAS. 5.5. PRENSAMENTO/ESMAGAMENTO - A ÁREA POSSUI VÁRIOS TRANSPORTADORES DE CORREIA COM PARTES MÓVEIS QUE PODEM GERAR PRENSAMENTO DE MEMBROS E/OU ESMAGAMENTO. NÃO SE APROXIME DE PARTES MÓVEIS E SÓ ACESSE OS TRANSPORTADORES QUE POSSUEM GRADES DE PROTEÇÃO CONFORME NR12, OU COM O EQUIPAMENTO PARADO E BLOQUEADO, CONFORME NORMA CORPORATIVA – NCSEGGE0002. 5.6. INTOXICAÇÃO POR GÁS - UTILIZAR DETECTOR DE GÁS AO TRABALHAR NO 5° PISO DA MÁQUINA. RISCO DE VAZAMENTO DE GÁS PRÓXIMO À CAMARA DE COMBUSTÃO. 6. RECOMENDAÇÃO DE MEIO AMBIENTE - REALIZAR A SEPARAÇÃO E DESCARTE DE RESTOS DE MANUTENÇÃO, INCLUINDO PEÇAS METÁLICAS, MADEIRA, BORRACHA E OUTROS NA BAIA DE DESCARTE DA OFICINA 410. - REALIZAR DESCARTE DE MATERIAIS RECICLÁVEIS NOS TAMBORES COLORIDOS CONFORME TIPO DE MATERIAL NA OFICINA 410.
B13: 2 | C13: US01-RD-SINT3-SISTP-ARMAZ-TRMIS-SCT | H13: 0010 | I13: 0013 | J13: NÃO SE APLICA
B14: 2 | C14: US01-RD-SINT3-SISTP-ARMAZ-TRMIS-SCT | H14: 0010 | I14: 0014 | J14: 1. DESENGRIPANTE GA LUB (FDS SCFISPQ1093) 2. SILICONE LOCTITE SUPERFLEX 595 (FDS SCFISPM0896) 3. COMPOSTO DESENGRAXANTE SOLVENTE (FDS SCFISPI3551) 4. COMPOSTO LIMPEZA DE CONTATOS ELÉTRICOS (FDS SCFISPI3599)
B15: 2 | C15: US01-RD-SINT3-SISTP-ARMAZ-TRMIS-SCT | H15: 0020 | J15: 1- SENSORES DE POSICIONAMENTO DA COMPORTA PRINCIPAL 1.1 REALIZAR A DESMONTAGEM DAS TAMPA DE PROTEÇÃO DOS TERMINAIS DE ALIMENTAÇÃO, RETIRANDO OS PARAFUSOS DE PROTEÇÃO. 1.2 VERIFICAR CONEXÕES, CASO NÃO TENHAM TERMINAIS, REALIZAR A INSTALAÇÃO NOS CABOS QUE ESTIVEREM FALTANDO. 1.3 CONFERIR AS CONEXÕES DOS CABOS, REALIZAR O REAPERTO E REALIZAR LIMPEZA INTERNA. 1.4 FECHAR A TAMPA DE PROTEÇÃO DOS CABOS DOS SENSORES, FIXANDO TODOS OS PARAFUSOS. 1.5 REALIZAR TESTE DE FUNCIONAMENTO DOS SENSORES. POSICIONAR UMA PEÇA METÁLICA NA FACE FRONTAL DE ATUAÇÃO DOS SENSORES E VERIFICAR SE O LED DE ACIONAMENTO IRÁ ACENDER. ( ) EXECUTADO ( ) NÃO EXECUTADO ------------------------------------------------------------- RECOMENDAÇÕES DE SEGURANÇA ESPECÍFICAS DAS ATIVIDADES 1. RISCO DE CORTE/PRENSAMENTO. - AO UTILIZAR FERRAMENTAS PERFURANTES, NÃO MANUSEAR CONTRA O CORPO. - UTILIZAR LUVAS ANTI-CORTE, O MATERIAL PODE POSSUIR ARESTAS CORTANTES E QUINA VIVAS - AO UTILIZAR CHAVES DE BOCA PARA ABERTURA DA GRADE, NÃO EXPOR AS MEMBROS A PRENSAMENTO. 2. RISCO DE PROJEÇÃO. - NAO DIRECIONAR AR COMPRIMIDO NO SENTIDO DO CORPO; - UTILIZAR ÓCULOS HERMÉTICO; 3. QUEDA HUMANA -REALIZAR ATIVIDADE POSICIONANDO-SE SOBRE PASSARELA DE ACESSO AOS SENSORES ------------------------------------------------------------- EXECUTANTES DECLARO QUE LI E COMPREENDI AS ATIVIDADES E AS RECOMENDAÇÕES DE SEGURANÇA DA OM. NOME________________________ REGISTRO____________________ ASSINATURA__________________ NOME________________________ REGISTRO____________________ ASSINATURA__________________ NOME________________________ REGISTRO____________________ ASSINATURA__________________ NOME________________________ REGISTRO____________________ ASSINATURA__________________ NOME________________________ REGISTRO____________________ ASSINATURA__________________
B16: 3 | C16: US01-RD-SINT3-SISTP-ARMAZ-TRMIS-SCT | H16: 0010 | J16: COMPORTA TREMONHA LIMPEZA PREV ELÉTRICA
B17: 3 | C17: US01-RD-SINT3-SISTP-ARMAZ-TRMIS-SCT | H17: 0010 | I17: 0010 | J17: NÃO SE APLICA
B18: 3 | C18: US01-RD-SINT3-SISTP-ARMAZ-TRMIS-SCT | H18: 0010 | I18: 0011 | J18: NÃO SE APLICA
B19: 3 | C19: US01-RD-SINT3-SISTP-ARMAZ-TRMIS-SCT | H19: 0010 | I19: 0012 | J19: 1. ABERTURA DA PPT: 1.1. A PPT DEVERÁ SER ABERTA E LIBERADA PELA EQUIPE DA OPERAÇÃO NO QUINTO PISO DA MÁQUINA DE SINTER 3 2.APRESENTAÇÃO DA EQUIPE: 2.1. LOCAL DE APRESENTAÇÃO: SALA DA INSPEÇÃO 2.2. TÉCNICO RESPONSÁVEL E TELEFONE ESTÁ NO CABEÇALHO DA ORDEM NO CAMPO (GPM). 3. TESTE DE EFICÁCIA 3.1. CONTROLADOR ELÉTRICA: CONFIRMAÇÃO DE AUSÊNCIA DE TENSÃO NO CIRCUITO DE FORÇA DO EQUIPAMENTO 3.2. CONTROLADOR MECÂNICA: NÃO SE APLICA 3.3. OPERAÇÃO: TESTE DE TENTATIVA DE COMANDO DO EQUIPAMENTO 3.4. O EXECUTANTE DEVE ACOMPANHAR O RESPONSÁVEL DA OPERAÇÃO DURANTE O TESTE DE EFICÁCIA DE BLOQUEIO NA ÁREA OPERACIONAL. 3. EPIS E EPCS ESPECIFICOS DA ÁREA - MÁSCARA CONTRA PÓ PFF1 - LUVAS. - ÓCULOS HÉRMETICO - DETECTOR MULTI-GÁS. 4. EPIS E EPCS ESPECIFICOS DA ATIVIDADE - ROUPAS ANTICHAMAS NR10. 5. RISCOS GERAIS DA ÁREA: 5.1 QUEDA HUMANA - PISO IRREGULAR, ESCORREGADIO COM DESNÍVEIS E ACÚMULO DE MATERIAIS. UTILIZE SEMPRE OS CORRIMÃOS AO SUBIR E DESCER ESCADAS E AO SE DESLOCAR SOBRE PASSARELAS - ANTES DE ACESSAR, AVALIE BEM O LOCAL PARA QUE NÃO SEJA SURPREENDIDO POR BURACOS, CHAPAS DE PISO SOLTAS, CORRIMÃOS AVARIADOS E DESNÍVEIS DE PISO, CASO SUA ROTA NÃO ESTEJA EM CONDIÇÕES SEGURAS, USE OUTRA ROTA QUE SEJA SEGURA E COMUNIQUE AO RESPONSAVEL PARA RESOLUÇÃO DA ANORMALIDADE. - NÃO ACESSAR PASSARELAS COM ACÚMULO DE MATERIAL, AO IDENTIFICAR SITUAÇÕES SEMELHANTES, IMEDIATAMENTE ISOLAR O LOCAL. 5.2. QUEDA DE MATERIAIS E FERRAMENTAS. - NÃO TRANSITAR SOB LOCAIS DE ATIVIDADES SOBREPOSTAS - NOS TRABALHOS EM ALTURA REALIZAR AMARRAÇÃO DAS FERRAMENTAS. - ARMAZENAR FERRAMENTAS DE PEQUENO PORTE EM RECIPIENTES ADEQUADOS, ELIMINANDO O RISCO DE QUEDA NA PARTE INFERIOR. - AO TRANSITAR SOB TRANSPORTADORES DE CORREIA, OLHAR PARA CIMA E VERIFICAR A EXISTÊNCIA DO RISCO DE QUEDA DE PEÇAS E/OU MATERIAL COMPACTADO NA ESTRUTURA. OBSERVE SE ELA TEM PROTEÇÕES ABAIXO CONTRA QUEDA DE MATERIAL, CASO NAO TENHA PROCURE OUTRA ROTA. 5.3. ATROPELAMENTO - RISCO DE ATROPELAMENTO POR MÁQUINAS DE LIMPEZA (RETROESCAVADEIRA, BOBCAT E CAMINHÕES) ENTRE OS TRANSPORTADORES - RISCO DE ATROPELAMENTO POR VEÍCULO AO TRANSITAR PELAS RUAS. - PARAR, OLHAR E ESCUTAR ANTES DE TRANSITAR EM LOCAIS COM PRESENÇA DE VEICULOS MOTORIZADOS, SE NECESSARIO UTILIZE OUTRA ROTA PARA DESLOCAMENTO. - NÃO PASSAR EMBAIXO DE MATERIAIS SUSPENSOS POR GUINDASTE, PONTE ROLANTE E TALHAS ELÉTRICAS. - NÃO ULTRAPASSAR ÁREAS ISOLADAS POR CORRENTES, FITAS E/OU CERQUITES, CASO SEJA NECESSÁRIO O ACESSO PEDIR AUTORIZAÇÃO A UM RESPONSÁVEL PELA ATIVIDADE. - NÃO FICAR POSICIONADO NO RAIO DE AÇÃO DA PARTE TRASEIRA DE MÁQUINAS E EQUIPAMENTOS, O MOTORISTA NÃO TEM VISÃO AMPLA EM MANOBRAS EM MARCHA RÉ. 5.4. PARTICULADOS EM SUSPENÇÃO (POEIRA) - USAR MÁSCARA CONTRA POEIRA FIXADA AO ROSTO DURANTE TODO TEMPO QUE ESTIVER A ÁREA COM EXPOSIÇÃO AO RISCO. - OBRIGATÓRIO A UTILIZAÇÃO DE MÁSCARA DE PROTEÇÃO CONTRA POEIRAS EM TODA A ÁREA DE SINTERIZAÇÃO E MATÉRIAS-PRIMAS. 5.5. PRENSAMENTO/ESMAGAMENTO - A ÁREA POSSUI VÁRIOS TRANSPORTADORES DE CORREIA COM PARTES MÓVEIS QUE PODEM GERAR PRENSAMENTO DE MEMBROS E/OU ESMAGAMENTO. NÃO SE APROXIME DE PARTES MÓVEIS E SÓ ACESSE OS TRANSPORTADORES QUE POSSUEM GRADES DE PROTEÇÃO CONFORME NR12, OU COM O EQUIPAMENTO PARADO E BLOQUEADO, CONFORME NORMA CORPORATIVA – NCSEGGE0002. 5.6. INTOXICAÇÃO POR GÁS - UTILIZAR DETECTOR DE GÁS AO TRABALHAR NO 5° PISO DA MÁQUINA. RISCO DE VAZAMENTO DE GÁS PRÓXIMO À CAMARA DE COMBUSTÃO. 6. RECOMENDAÇÃO DE MEIO AMBIENTE - REALIZAR A SEPARAÇÃO E DESCARTE DE RESTOS DE MANUTENÇÃO, INCLUINDO PEÇAS METÁLICAS, MADEIRA, BORRACHA E OUTROS NA BAIA DE DESCARTE DA OFICINA 410. - REALIZAR DESCARTE DE MATERIAIS RECICLÁVEIS NOS TAMBORES COLORIDOS CONFORME TIPO DE MATERIAL NA OFICINA 410.
B20: 3 | C20: US01-RD-SINT3-SISTP-ARMAZ-TRMIS-SCT | H20: 0010 | I20: 0013 | J20: NÃO SE APLICA
B21: 3 | C21: US01-RD-SINT3-SISTP-ARMAZ-TRMIS-SCT | H21: 0010 | I21: 0014 | J21: 1. DESENGRIPANTE GA LUB (FDS SCFISPQ1093) 2. SILICONE LOCTITE SUPERFLEX 595 (FDS SCFISPM0896) 3. COMPOSTO DESENGRAXANTE SOLVENTE (FDS SCFISPI3551) 4. COMPOSTO LIMPEZA DE CONTATOS ELÉTRICOS (FDS SCFISPI3599)
B22: 3 | C22: US01-RD-SINT3-SISTP-ARMAZ-TRMIS-SCT | H22: 0020 | J22: 1- LIMPEZA SENSORES DE POSIÇÃO 1.1 REALIZAR LIMPEZA EXTERNA DOS SENSORES DEPOSIÇÃO UTILIZANDO SOPRADOR ELÉTRICO/AR COMPRIMIDO, PINCEL E TOALHAS DE PANO; 1.2 CASO ENCONTRE ALGUMA ANORMALIDADE NOS SENSORES, INFORMAR IMEDIATAMENTE AO INSPETOR;(CABO SOLTO, SENSOR COM FOLGA NA FIXAÇÃO, CARCAÇA DANIFICADA). ( ) EXECUTADO ( ) NÃO EXECUTADO ------------------------------------------------------------- RECOMENDAÇÕES DE SEGURANÇA ESPECÍFICAS DAS ATIVIDADES 1. RISCO DE CORTE. - AO UTILIZAR FERRAMENTAS CORTANTES E PERFURANTES, NÃO MANUSEAR CONTRA O CORPO. - UTILIZAR LUVAS ANTI-CORTE. O MATERIAL PODE POSSUIR ARRESTAS CORTANTES E QUINAS VIVAS - NÃO UTILIZAR EXCESSO DE FORÇA AO MANUSEAR FERRAMENTAS, POIS ESTAS PODEM ESCAPAR DA MÃO E OCASIONAR CORTE E PRENSAMENTO 2. RISCO DE PROJEÇÃO. - NAO DIRECIONAR AR COMPRIMIDO CONTRA O CORPO, CASO A ATIVIDADE GERE MUITO MATERIAL PARTICULADO SUSPENSO DEVIDO O USO DE SOPRADOR ELÉTRICO, UTILIZAR ÓCULOS HÉMETICO. EXECUTANTES DECLARO QUE LI E COMPREENDI AS ATIVIDADES E AS RECOMENDAÇÕES DE SEGURANÇA DA OM. NOME________________________ REGISTRO____________________ ASSINATURA__________________ NOME________________________ REGISTRO____________________ ASSINATURA__________________ NOME________________________ REGISTRO____________________ ASSINATURA__________________ NOME________________________ REGISTRO____________________ ASSINATURA__________________ NOME________________________ REGISTRO____________________ ASSINATURA__________________
B23: 3 | C23: US01-RD-SINT3-SISTP-ARMAZ-TRMIS-SCT | H23: 0030 | J23: 1- MOTORE ELÉTRICO COMPORTA PRINCIPAL 1.1 EFETUAR LIMPEZA DAS ALETAS DE REFRIGERAÇÃO DO MOTOR UTILIZANDO ESPÁTULA E ESCOVA DE AÇO PARA RETIRAR O EXCESSO DE SUJEIRA IMPREGNADA. 1.2 UTILIZAR SOPRADOR ELÉTRICO/AR COMPRIMIDO E TOALHAS DE PANO PARA FINALIZAR A LIMPEZA DAS ALETAS DE REFRIGERAÇÃO DO MOTOR. 1.3 REALIZAR LIMPEZA NA TAMPA DEFLETORA E NA VENTOINHA, UTILIZANDO ESPÁTULA, ESCOVA DE AÇO, SOPRADOR ELÉTRICO/AR COMPRIMIDO E TOALHAS DE PANO ( ) EXECUTADO ( ) NÃO EXECUTADO ------------------------------------------------------------- RECOMENDAÇÕES DE SEGURANÇA ESPECÍFICAS DAS ATIVIDADES 1. RISCO DE CORTE. - AO UTILIZAR FERRAMENTAS CORTANTES E PERFURANTES, NÃO MANUSEAR CONTRA O CORPO. - UTILIZAR LUVAS ANTI-CORTE. O MATERIAL PODE POSSUIR ARRESTAS CORTANTES E QUINAS VIVAS - NÃO UTILIZAR EXCESSO DE FORÇA AO MANUSEAR FERRAMENTAS, POIS ESTAS PODEM ESCAPAR DA MÃO E OCASIONAR CORTE E PRENSAMENTO 2. RISCO DE PROJEÇÃO. - NAO DIRECIONAR AR COMPRIMIDO CONTRA O CORPO, CASO A ATIVIDADE GERE MUITO MATERIAL PARTICULADO SUSPENSO DEVIDO O USO DE SOPRADOR ELÉTRICO, UTILIZAR ÓCULOS HÉMETICO. EXECUTANTES DECLARO QUE LI E COMPREENDI AS ATIVIDADES E AS RECOMENDAÇÕES DE SEGURANÇA DA OM. NOME________________________ REGISTRO____________________ ASSINATURA__________________ NOME________________________ REGISTRO____________________ ASSINATURA__________________ NOME________________________ REGISTRO____________________ ASSINATURA__________________ NOME________________________ REGISTRO____________________ ASSINATURA__________________ NOME________________________ REGISTRO____________________ ASSINATURA__________________
B24: 4 | D24: 10380837 | H24: 0010 | J24: COMPORTA TREMONHA MOTOR ELÉTRICO
B25: 4 | D25: 10380837 | H25: 0010 | I25: 0010 | J25: NÃO SE APLICA
B26: 4 | D26: 10380837 | H26: 0010 | I26: 0011 | J26: NÃO SE APLICA
